## 10.04 Finally Block 🧹

There's an interesting question that might pop up in your mind — what happens when an error occurs in your program? You're right there, handling the exception, possibly resolving or logging it; but does the rest of your code execute? Does it stop? Or, as Dickens might say, "It was the best of codes, it was the worst of codes"?

The `finally` block is here to answer all those queries and be the Charles Dickens of your Python story.

🔍 **What is the Finally Block?**

The `finally` statement in Python is somewhat of a safety net. It contains the critical operations that must be performed—no matter what— before the code concludes its execution. Even if an exception is thrown in the middle of running your code, the `finally` block guarantees that the operations inside it are executed. 

Imagine this as akin to a mother making her child clean up their toys, regardless of whether they had a fun day of play or a tantrum-filled one. 

Here's a little taste of how this looks in Python:

```python
try:
    a = 5 / 0
except ZeroDivisionError:
    print('Error: Dividing by zero is not cool 😎.')
finally:
    print('This is it! The end. 🏁.')
```

In the above code, even though a `ZeroDivisionError` exception is raised, your `finally` block still gets its moment to shine by printing the line "This is it! The end." before the code exits gracefully.

✨ **Why for the Love of Python Do We Use Finally Block?**

In real-world applications, you often have resources that need a proper closure or actions that need to be performed irrespective of whether any exceptions have occurred. This could be about closing a file, releasing a network resource, or tidying up some system resources.

By putting such statements in the `finally` block, you're assuring that your code isn't leaving any loose ends, ensuring a smooth and clean exit.

Let’s reinforce this concept with a concrete example:

```python
try:
    file = open('python_rules.txt', 'w')
    file.write('Python is awesome! ') 
except IOError:
    print('Oops! File not found or something went wrong 😬.')
finally:
    print('Closing the file now...')
    file.close()
```

In this scenario, regardless of whether you successfully write to the file or encounter an `IOError`, your code will always close the file in the `finally` block like a dutiful cleanup crew.

So there you go, folks! The `finally` block is truly your knight in shining Python that ensures a graceful exit strategy for your code. Its usage allows your program to close on a high note, no matter how rugged the road leading up to it was. It’s your little piece of 'And they lived happily ever after...' in the fairy-tale of Python. 🐍🏰💖

Until next time, happy coding! ⌨️💡🚀